<?xml version="1.0"?>
<!-- This URDF was automatically created by SolidWorks to URDF Exporter! Copy from MirRbot and
Modified by TommyTo (tommy@datadesign.engineering)
For more information, please see http://wiki.ros.org/sw_urdf_exporter -->
<robot name="dde_amr" xmlns:xacro="http://ros.org/wiki/xacro">

    <xacro:arg name="is_ignition" default="true"/>

    <!-- Include Gazebo Parameters -->
    <xacro:include filename="$(find dde_amr_description)/urdf/dde_amr_gazebo.xacro"/>
    <!--<link name="base_footprint" /> -->
    <!-- Setting link for base_link-->
    <link name="base_link">

        <inertial>
            <origin xyz="0.264961530183372 0.00225996356394289 0.112161694553598" rpy="0 0 0" />
            <mass value="28.3239204847698" />
            <inertia ixx="0.136989288705436" ixy="-0.00013586267118142" ixz="0.000216303712387318"
                iyy="0.455306795955337" iyz="0.00115313054501806" izz="0.538335903712105" />
        </inertial>

        <visual>
            <origin rpy="0 0 0" xyz="0 0 0" />
            <geometry>
                <mesh filename="package://dde_amr_description/meshes/base_link.STL" />
            </geometry>
            <material name="">
                <color rgba="0.792156862745098 0.819607843137255 0.933333333333333 1" />
            </material>
        </visual>

        <collision>
            <origin rpy="0 0 0" xyz="0 0 0" />
            <geometry>
                <mesh filename="package://dde_amr_description/meshes/base_link.STL" />
            </geometry>
        </collision>
    </link>
    <!-- Settings joint for base_link 
    <joint name="base_joint" type="fixed">
        <parent link="base_footprint" />
        <child link="base_link" />
        <origin xyz="0 0 0.033" rpy="0 0 0" />
    </joint>
    -->
    <!-- Setting link for left_wheel_link-->
    <link name="left_wheel_link">

        <inertial>
            <origin xyz="-3.3273E-13 -1.08E-12 -0.004498" rpy="0 0 0" />
            <mass value="0.94018" />
            <inertia ixx="0.0030878" ixy="-1.1841E-19" ixz="9.8263E-18"
                iyy="0.0030878" iyz="-5.9629E-15" izz="0.0058343" />
        </inertial>

        <visual>
            <origin xyz="0 0 0" rpy="0 0 0" />
            <geometry>
                <mesh filename="package://dde_amr_description/meshes/left_wheel_link.STL" />
            </geometry>
            <material name="">
                <color rgba="0.79216 0.81961 0.93333 1" />
            </material>
        </visual>

        <collision>
            <origin xyz="0 0 0" rpy="0 0 0" />
            <geometry>
                <mesh filename="package://dde_amr_description/meshes/left_wheel_link.STL" />
            </geometry>
        </collision>
    </link>

    <!-- Settings joint for left_wheel_link -->
    <joint name="left_wheel_joint" type="continuous">
        <parent link="base_link" />
        <child link="left_wheel_link" />
        <axis xyz="0 0 1" />
        <origin rpy="-1.5708 0 0" xyz="-0.013203 0.24052 0.064" />
        <limit effort="10" velocity="10" />
        <dynamics damping="0.1" friction="0.01" />
    </joint>


    <!-- Setting link for right_wheel_link-->
    <link name="right_wheel_link">
        <inertial>
            <origin xyz="-3.29292149103821E-13 -5.41650058138998E-14 0.00450198043741312"
                rpy="0 0 0" />
            <mass value="0.94018365156767" />
            <inertia ixx="0.00308782611811812" ixy="-4.64758677897525E-19"
                ixz="-9.25039554694071E-18"
                iyy="0.00308782611811811" iyz="-5.97721718042081E-15" izz="0.00583434941184945" />
        </inertial>

        <visual>
            <origin xyz="0 0 0" rpy="0 0 0" />
            <geometry>
                <mesh filename="package://dde_amr_description/meshes/right_wheel_link.STL" />
            </geometry>
            <material name="">
                <color rgba="0.792156862745098 0.819607843137255 0.933333333333333 1" />
            </material>
        </visual>

        <collision>
            <origin xyz="0 0 0" rpy="0 0 0" />
            <geometry>
                <mesh filename="package://dde_amr_description/meshes/right_wheel_link.STL" />
            </geometry>
        </collision>

    </link>

    <!-- Settings joint for right_wheel_link -->
    <joint name="right_wheel_joint" type="continuous">
        <parent link="base_link" />
        <child link="right_wheel_link" />
        <axis xyz="0 0 -1" />
        <origin rpy="-1.5708 0 0" xyz="-0.013203 -0.24048 0.064" />
        <limit effort="10" velocity="10" />
        <dynamics damping="0.1" friction="0.01" />
    </joint>

    <!-- Settings link for caster_one_link -->
    <link name="caster_one_link">

        <inertial>
            <origin
                xyz="0.0181380765705021 -0.00032074694194453 -0.0524126710459661" rpy="0 0 0" />
            <mass value="0.112454546873097" />
            <inertia ixx="8.80309430168958E-05" ixy="-1.18104583145472E-10"
                ixz="5.24388785602479E-07"
                iyy="6.46284651214001E-05" iyz="-4.76570604714267E-11" izz="0.000111462019026295" />
        </inertial>

        <visual>
            <origin xyz="0 0 0" rpy="0 0 0" />
            <geometry>
                <mesh filename="package://dde_amr_description/meshes/caster_one_link.STL" />
            </geometry>
            <material name="">
                <color rgba="0.792156862745098 0.819607843137255 0.933333333333333 1" />
            </material>
        </visual>

        <collision>
            <origin xyz="0 0 0" rpy="0 0 0" />
            <geometry>
                <mesh filename="package://dde_amr_description/meshes/caster_one_link.STL" />
            </geometry>
        </collision>

    </link>

    <!-- Settings joint for caster_one_link -->
    <joint name="caster_one_joint" type="continuous">
        <parent link="base_link" />
        <child link="caster_one_link" />
        <origin xyz="0.5498 1.7068E-05 0.0765" rpy="0 0 0" />
        <parent link="base_link" />
        <child link="caster" />
        <axis xyz="0 0 -1" />
        <limit effort="10" velocity="10" />
        <dynamics damping="0.01" friction="0.01" />
    </joint>

    <!-- Settings link for caster_wheel_link -->
    <link name="caster_wheel_link">
        <inertial>
            <origin xyz="3.06699110552699E-13 4.84001727585337E-13 0.00329389999808982" rpy="0 0 0" />
            <mass value="0.15047968496888" />
            <inertia ixx="6.68462901317433E-05" ixy="-1.49603451413595E-21"
                ixz="8.62486352905831E-20"
                iyy="6.68462901317433E-05" iyz="1.93444951645268E-22" izz="0.000122637940378903" />
        </inertial>
        <visual>
            <origin xyz="0 0 0" rpy="0 0 0" />
            <geometry>
                <mesh filename="package://dde_amr_description/meshes/caster_wheel_link.STL" />
            </geometry>
            <material name="">
                <color rgba="0.792156862745098 0.819607843137255 0.933333333333333 1" />
            </material>
        </visual>
        <collision>
            <origin xyz="0 0 0" rpy="0 0 0" />
            <geometry>
                <mesh filename="package://dde_amr_description/meshes/caster_wheel_link.STL" />
            </geometry>
        </collision>
    </link>
     <!-- Settings joint for caster_wheel_link -->
    <joint name="caster_wheel_joint" type="continuous">
        <parent link="base_link" />
        <child link="caster_wheel_link" />
        <origin rpy="-1.5708 0 0" xyz="-0.019972 -0.0032939 -0.075" />
        <axis xyz="0 0 -1" />
        <limit effort="10" velocity="10" />
        <dynamics damping="0.01" friction="0.01" />
    </joint>


     <!-- Settings link for front_lidar_link -->
    <link name="front_lidar_link">

        <inertial>
            <origin xyz="-0.00207301754595379 -5.40732895935483E-05 -0.0528498038220741" rpy="0 0 0" />
            <mass value="0.208748881672676" />
            <inertia ixx="0.000140216872845025" ixy="4.07869701191182E-08" ixz="2.51235596599784E-06" 
            iyy="0.00013732411854646" iyz="-1.71903136748626E-08" izz="9.31238252061991E-05"/>
        </inertial>

        <visual>
            <origin xyz="0 0 0" rpy="0 0 0" />
            <geometry>
                <mesh filename="package://dde_amr_description/meshes/front_lidar_link.STL" />
            </geometry>
            <material name="">
                <color rgba="0.792156862745098 0.819607843137255 0.933333333333333 1" />
            </material>
        </visual>

        <collision>
            <origin xyz="0 0 0" rpy="0 0 0" />
            <geometry>
                <mesh filename="package://dde_amr_description/meshes/front_lidar_link.STL" />
            </geometry>
        </collision>
    </link>
    <!-- Settings joint for front_lidar_link -->
    <joint
        name="front_lidar_joint"
        type="continuous">
        <origin xyz="0.7598 0.0027433 0.14323" rpy="0 0 0" />
        <parent link="base_link" />
        <child link="front_lidar_link" />
        <axis xyz="0 0 -1" />
    </joint>

     <!-- Settings link for rear_lidar_link -->
    <link name="rear_lidar_link">
        <inertial>
            <origin xyz="0.00207355210295557 3.00653137750573E-05 -0.0528498007205547" rpy="0 0 0" />
            <mass value="0.208748884092951" />
            <inertia ixx="0.00014021743447073" ixy="7.27574496610714E-09" ixz="-2.51199717415079E-06" 
            iyy="0.000137323574056695" iyz="4.62814688002168E-08" izz="9.31238270300697E-05"/>
        </inertial>
        <visual>
            <origin xyz="0 0 0" rpy="0 0 0" />
            <geometry>
                <mesh filename="package://dde_amr_description/meshes/rear_lidar_link.STL" />
            </geometry>
            <material name="">
                <color rgba="0.792156862745098 0.819607843137255 0.933333333333333 1" />
            </material>
        </visual>
        <collision>
            <origin xyz="0 0 0" rpy="0 0 0" />
            <geometry>
                <mesh filename="package://dde_amr_description/meshes/rear_lidar_link.STL" />
            </geometry>
        </collision>
    </link>

    <!-- Settings joint for rear_lidar_joint -->
    <joint name="rear_lidar_joint" type="continuous">
        <origin xyz="-0.19691 -0.18272 0.13918" rpy="0 0 0" />
        <parent link="base_link" />
        <child link="rear_lidar_link" />
        <axis xyz="0 0 1" />
    </joint>
    


</robot>